RuntimeError: module compiled against API version 0xf but this version of numpy is 0xe
  0%|          | 0/1 [00:00<?, ?it/s]
  0%|          | 0/112 [00:00<?, ?it/s][A
  1%|          | 1/112 [18:18<33:52:07, 1098.45s/it][A
  2%|▏         | 2/112 [18:32<14:03:55, 460.33s/it] [A
  3%|▎         | 3/112 [18:33<7:35:28, 250.72s/it] [A
  4%|▍         | 5/112 [18:44<3:19:23, 111.81s/it][A
 12%|█▎        | 14/112 [19:17<44:05, 26.99s/it]  [A
 65%|██████▌   | 73/112 [28:43<07:35, 11.68s/it][A
 69%|██████▉   | 77/112 [28:43<06:16, 10.77s/it][A
 71%|███████   | 79/112 [28:51<05:43, 10.41s/it][A
 72%|███████▏  | 81/112 [28:55<05:03,  9.81s/it][A
 79%|███████▉  | 89/112 [28:57<02:42,  7.07s/it][A
 87%|████████▋ | 97/112 [29:00<01:16,  5.10s/it][A100%|██████████| 112/112 [29:00<00:00, 15.54s/it]
100%|██████████| 1/1 [29:10<00:00, 1750.18s/it]100%|██████████| 1/1 [29:10<00:00, 1750.18s/it]
Exception ignored in: <function Pool.__del__ at 0x2b07667c94c0>
Traceback (most recent call last):
  File "/home/n9455647/.conda/envs/conda_test/lib/python3.8/multiprocessing/pool.py", line 268, in __del__
  File "/home/n9455647/.conda/envs/conda_test/lib/python3.8/multiprocessing/queues.py", line 362, in put
AttributeError: 'NoneType' object has no attribute 'dumps'
