RuntimeError: module compiled against API version 0xf but this version of numpy is 0xe
  0%|          | 0/1 [00:00<?, ?it/s]
  0%|          | 0/112 [00:00<?, ?it/s][A
  1%|          | 1/112 [6:41:02<741:56:29, 24062.96s/it][A
  3%|▎         | 3/112 [7:22:33<216:49:19, 7161.09s/it] [A
  9%|▉         | 10/112 [7:39:32<46:22:54, 1637.00s/it][A
 11%|█         | 12/112 [8:25:20<43:41:43, 1573.04s/it][A
 36%|███▌      | 40/112 [8:29:55<5:31:40, 276.40s/it]  [A
 44%|████▍     | 49/112 [8:40:27<3:50:28, 219.50s/it][A
 65%|██████▌   | 73/112 [9:16:28<1:39:33, 153.17s/it][A
 66%|██████▌   | 74/112 [9:31:20<1:50:52, 175.06s/it][A
 69%|██████▉   | 77/112 [9:34:17<1:34:29, 161.98s/it][A
 81%|████████▏ | 91/112 [9:34:17<32:23, 92.55s/it]   [A
 87%|████████▋ | 97/112 [9:34:19<18:20, 73.36s/it][A100%|██████████| 112/112 [9:34:19<00:00, 307.67s/it]
100%|██████████| 1/1 [9:34:28<00:00, 34468.68s/it]100%|██████████| 1/1 [9:34:28<00:00, 34468.68s/it]
Exception ignored in: <function Pool.__del__ at 0x2b770d8db430>
Traceback (most recent call last):
  File "/home/n9455647/.conda/envs/conda_test/lib/python3.8/multiprocessing/pool.py", line 268, in __del__
  File "/home/n9455647/.conda/envs/conda_test/lib/python3.8/multiprocessing/queues.py", line 362, in put
AttributeError: 'NoneType' object has no attribute 'dumps'
