RuntimeError: module compiled against API version 0xf but this version of numpy is 0xe
  0%|          | 0/1 [00:00<?, ?it/s]
  0%|          | 0/112 [00:00<?, ?it/s][A
  1%|          | 1/112 [1:19:40<147:24:16, 4780.69s/it][A
  2%|▏         | 2/112 [1:35:29<77:11:54, 2526.50s/it] [A
 15%|█▌        | 17/112 [1:37:39<5:06:46, 193.75s/it] [A
 21%|██▏       | 24/112 [1:38:24<2:59:17, 122.24s/it][A
 47%|████▋     | 53/112 [1:38:44<37:19, 37.97s/it]   [A
 53%|█████▎    | 59/112 [1:39:29<28:57, 32.78s/it][A
 65%|██████▌   | 73/112 [2:02:11<36:28, 56.12s/it][A
 66%|██████▌   | 74/112 [2:13:29<49:33, 78.26s/it][A
 70%|██████▉   | 78/112 [2:14:55<38:54, 68.65s/it][A
 86%|████████▌ | 96/112 [2:15:00<08:48, 33.06s/it][A
 88%|████████▊ | 98/112 [2:15:12<07:13, 30.98s/it][A
 94%|█████████▍| 105/112 [2:15:23<02:40, 22.87s/it][A100%|██████████| 112/112 [2:15:23<00:00, 72.53s/it]
100%|██████████| 1/1 [2:15:33<00:00, 8133.43s/it]100%|██████████| 1/1 [2:15:33<00:00, 8133.43s/it]
Exception ignored in: <function Pool.__del__ at 0x2b4c540ba430>
Traceback (most recent call last):
  File "/home/n9455647/.conda/envs/conda_test/lib/python3.8/multiprocessing/pool.py", line 268, in __del__
  File "/home/n9455647/.conda/envs/conda_test/lib/python3.8/multiprocessing/queues.py", line 362, in put
AttributeError: 'NoneType' object has no attribute 'dumps'
