RuntimeError: module compiled against API version 0xf but this version of numpy is 0xe
  0%|          | 0/1 [00:00<?, ?it/s]
  0%|          | 0/112 [00:00<?, ?it/s][A
  1%|          | 1/112 [8:45:10<971:35:15, 31510.95s/it][A
  2%|▏         | 2/112 [15:34:47<838:12:11, 27432.10s/it][A
  8%|▊         | 9/112 [17:12:22<134:29:28, 4700.67s/it] [A
 17%|█▋        | 19/112 [17:26:41<45:39:36, 1767.49s/it][A
 18%|█▊        | 20/112 [18:54:22<52:36:04, 2058.31s/it][A
 65%|██████▌   | 73/112 [20:38:35<4:09:23, 383.69s/it]  [A
 66%|██████▌   | 74/112 [22:06:50<5:13:42, 495.34s/it][A
 71%|███████▏  | 80/112 [22:07:15<3:41:27, 415.24s/it][A
 73%|███████▎  | 82/112 [22:14:15<3:20:13, 400.45s/it][A
 77%|███████▋  | 86/112 [22:15:26<2:25:12, 335.10s/it][A
 84%|████████▍ | 94/112 [22:15:35<1:07:41, 225.61s/it][A
 92%|█████████▏| 103/112 [22:15:45<22:13, 148.13s/it] [A
 96%|█████████▌| 107/112 [22:16:04<10:11, 122.35s/it][A100%|██████████| 112/112 [22:16:04<00:00, 715.75s/it]
100%|██████████| 1/1 [22:16:13<00:00, 80173.18s/it]100%|██████████| 1/1 [22:16:13<00:00, 80173.18s/it]
Exception ignored in: <function Pool.__del__ at 0x2ba91bd98430>
Traceback (most recent call last):
  File "/home/n9455647/.conda/envs/conda_test/lib/python3.8/multiprocessing/pool.py", line 268, in __del__
  File "/home/n9455647/.conda/envs/conda_test/lib/python3.8/multiprocessing/queues.py", line 362, in put
AttributeError: 'NoneType' object has no attribute 'dumps'
