RuntimeError: module compiled against API version 0xf but this version of numpy is 0xe
  0%|          | 0/1 [00:00<?, ?it/s]
  0%|          | 0/112 [00:00<?, ?it/s][A
  1%|          | 1/112 [14:54<27:35:41, 894.97s/it][A
  4%|▍         | 5/112 [14:55<3:57:57, 133.43s/it] [A
  5%|▌         | 6/112 [14:56<3:01:11, 102.56s/it][A
  7%|▋         | 8/112 [15:00<1:47:58, 62.30s/it] [A
  8%|▊         | 9/112 [15:18<1:30:14, 52.57s/it][A
 32%|███▏      | 36/112 [15:20<07:01,  5.55s/it] [A
 35%|███▍      | 39/112 [15:20<05:56,  4.88s/it][A
 46%|████▌     | 51/112 [15:26<03:06,  3.05s/it][A
 49%|████▉     | 55/112 [15:29<02:32,  2.67s/it][A
 65%|██████▌   | 73/112 [23:32<09:49, 15.11s/it][A
 68%|██████▊   | 76/112 [23:34<08:07, 13.55s/it][A
 74%|███████▍  | 83/112 [23:37<04:50, 10.01s/it][A
 92%|█████████▏| 103/112 [23:37<00:43,  4.81s/it][A100%|██████████| 112/112 [23:37<00:00, 12.66s/it]
100%|██████████| 1/1 [23:46<00:00, 1426.82s/it]100%|██████████| 1/1 [23:46<00:00, 1426.82s/it]
Exception ignored in: <function Pool.__del__ at 0x2ae266b084c0>
Traceback (most recent call last):
  File "/home/n9455647/.conda/envs/conda_test/lib/python3.8/multiprocessing/pool.py", line 268, in __del__
  File "/home/n9455647/.conda/envs/conda_test/lib/python3.8/multiprocessing/queues.py", line 362, in put
AttributeError: 'NoneType' object has no attribute 'dumps'
